2024-12-26 23:01:28,598 - ERROR - Error storing batch data
Traceback (most recent call last):
  File "/Users/temitopebadekale/Documents/personal project/dialogueRepo/connector.py", line 103, in store_data
    conn.execute(sql)
duckdb.duckdb.ConversionException: Conversion Error: Could not convert string 'peter82@johnson.com' to INT32
2024-12-26 23:03:50,200 - ERROR - Error storing batch data
Traceback (most recent call last):
  File "/Users/temitopebadekale/Documents/personal project/dialogueRepo/connector.py", line 103, in store_data
    conn.execute(sql)
duckdb.duckdb.ConversionException: Conversion Error: Could not convert string 'peter82@johnson.com' to INT32
2024-12-26 23:07:05,255 - ERROR - Error storing batch data
Traceback (most recent call last):
  File "/Users/temitopebadekale/Documents/personal project/dialogueRepo/connector.py", line 107, in store_data
    conn.execute(sql)
duckdb.duckdb.ConversionException: Conversion Error: Could not convert string 'peter82@johnson.com' to INT32
2024-12-26 23:29:53,724 - ERROR - Error storing batch data
Traceback (most recent call last):
  File "/Users/temitopebadekale/Documents/personal project/dialogueRepo/connector.py", line 109, in store_data
    conn.execute(sql)
duckdb.duckdb.BinderException: Binder Error: The specified columns as conflict target are not referenced by a UNIQUE/PRIMARY KEY CONSTRAINT or INDEX
2024-12-26 23:31:36,636 - ERROR - Error storing batch data
Traceback (most recent call last):
  File "/Users/temitopebadekale/Documents/personal project/dialogueRepo/connector.py", line 109, in store_data
    conn.execute(sql)
duckdb.duckdb.BinderException: Binder Error: The specified columns as conflict target are not referenced by a UNIQUE/PRIMARY KEY CONSTRAINT or INDEX
2024-12-26 23:39:44,930 - ERROR - Error storing batch data
Traceback (most recent call last):
  File "/Users/temitopebadekale/Documents/personal project/dialogueRepo/connector.py", line 111, in store_data
    conn.execute(sql)
duckdb.duckdb.BinderException: Binder Error: The specified columns as conflict target are not referenced by a UNIQUE/PRIMARY KEY CONSTRAINT or INDEX
2024-12-26 23:41:19,327 - ERROR - Error storing batch data
Traceback (most recent call last):
  File "/Users/temitopebadekale/Documents/personal project/dialogueRepo/connector.py", line 111, in store_data
    conn.execute(sql)
duckdb.duckdb.BinderException: Binder Error: The specified columns as conflict target are not referenced by a UNIQUE/PRIMARY KEY CONSTRAINT or INDEX
2024-12-26 23:42:18,280 - ERROR - Error storing batch data
Traceback (most recent call last):
  File "/Users/temitopebadekale/Documents/personal project/dialogueRepo/connector.py", line 111, in store_data
    conn.execute(sql)
duckdb.duckdb.BinderException: Binder Error: The specified columns as conflict target are not referenced by a UNIQUE/PRIMARY KEY CONSTRAINT or INDEX
2024-12-26 23:42:26,766 - ERROR - Error storing batch data
Traceback (most recent call last):
  File "/Users/temitopebadekale/Documents/personal project/dialogueRepo/connector.py", line 111, in store_data
    conn.execute(sql)
duckdb.duckdb.BinderException: Binder Error: The specified columns as conflict target are not referenced by a UNIQUE/PRIMARY KEY CONSTRAINT or INDEX
2024-12-26 23:43:18,892 - ERROR - Error storing batch data
Traceback (most recent call last):
  File "/Users/temitopebadekale/Documents/personal project/dialogueRepo/connector.py", line 111, in store_data
    conn.execute(sql)
duckdb.duckdb.BinderException: Binder Error: The specified columns as conflict target are not referenced by a UNIQUE/PRIMARY KEY CONSTRAINT or INDEX
2024-12-27 00:03:18,324 - ERROR - Error storing batch data
Traceback (most recent call last):
  File "/Users/temitopebadekale/Documents/personal project/dialogueRepo/connector.py", line 112, in store_data
    conn.execute(sql)
duckdb.duckdb.ConversionException: Conversion Error: Could not convert string 'peter82@johnson.com' to INT32
2024-12-27 10:38:01,439 - ERROR - Error fetching data for offset=0
Traceback (most recent call last):
  File "/Users/temitopebadekale/opt/anaconda3/envs/py3.10/lib/python3.10/site-packages/urllib3/connection.py", line 198, in _new_conn
    sock = connection.create_connection(
  File "/Users/temitopebadekale/opt/anaconda3/envs/py3.10/lib/python3.10/site-packages/urllib3/util/connection.py", line 85, in create_connection
    raise err
  File "/Users/temitopebadekale/opt/anaconda3/envs/py3.10/lib/python3.10/site-packages/urllib3/util/connection.py", line 73, in create_connection
    sock.connect(sa)
ConnectionRefusedError: [Errno 61] Connection refused

The above exception was the direct cause of the following exception:

Traceback (most recent call last):
  File "/Users/temitopebadekale/opt/anaconda3/envs/py3.10/lib/python3.10/site-packages/urllib3/connectionpool.py", line 787, in urlopen
    response = self._make_request(
  File "/Users/temitopebadekale/opt/anaconda3/envs/py3.10/lib/python3.10/site-packages/urllib3/connectionpool.py", line 493, in _make_request
    conn.request(
  File "/Users/temitopebadekale/opt/anaconda3/envs/py3.10/lib/python3.10/site-packages/urllib3/connection.py", line 445, in request
    self.endheaders()
  File "/Users/temitopebadekale/opt/anaconda3/envs/py3.10/lib/python3.10/http/client.py", line 1278, in endheaders
    self._send_output(message_body, encode_chunked=encode_chunked)
  File "/Users/temitopebadekale/opt/anaconda3/envs/py3.10/lib/python3.10/http/client.py", line 1038, in _send_output
    self.send(msg)
  File "/Users/temitopebadekale/opt/anaconda3/envs/py3.10/lib/python3.10/http/client.py", line 976, in send
    self.connect()
  File "/Users/temitopebadekale/opt/anaconda3/envs/py3.10/lib/python3.10/site-packages/urllib3/connection.py", line 276, in connect
    self.sock = self._new_conn()
  File "/Users/temitopebadekale/opt/anaconda3/envs/py3.10/lib/python3.10/site-packages/urllib3/connection.py", line 213, in _new_conn
    raise NewConnectionError(
urllib3.exceptions.NewConnectionError: <urllib3.connection.HTTPConnection object at 0x11bdc3910>: Failed to establish a new connection: [Errno 61] Connection refused

The above exception was the direct cause of the following exception:

Traceback (most recent call last):
  File "/Users/temitopebadekale/opt/anaconda3/envs/py3.10/lib/python3.10/site-packages/requests/adapters.py", line 667, in send
    resp = conn.urlopen(
  File "/Users/temitopebadekale/opt/anaconda3/envs/py3.10/lib/python3.10/site-packages/urllib3/connectionpool.py", line 841, in urlopen
    retries = retries.increment(
  File "/Users/temitopebadekale/opt/anaconda3/envs/py3.10/lib/python3.10/site-packages/urllib3/util/retry.py", line 519, in increment
    raise MaxRetryError(_pool, url, reason) from reason  # type: ignore[arg-type]
urllib3.exceptions.MaxRetryError: HTTPConnectionPool(host='localhost', port=8000): Max retries exceeded with url: /v1/patients?offset=0&limit=100&sort_field=last_name&sort_dir=asc (Caused by NewConnectionError('<urllib3.connection.HTTPConnection object at 0x11bdc3910>: Failed to establish a new connection: [Errno 61] Connection refused'))

During handling of the above exception, another exception occurred:

Traceback (most recent call last):
  File "/Users/temitopebadekale/Documents/personal project/dialogueRepo/connector.py", line 26, in fetch_page
    response = requests.get(
  File "/Users/temitopebadekale/opt/anaconda3/envs/py3.10/lib/python3.10/site-packages/requests/api.py", line 73, in get
    return request("get", url, params=params, **kwargs)
  File "/Users/temitopebadekale/opt/anaconda3/envs/py3.10/lib/python3.10/site-packages/requests/api.py", line 59, in request
    return session.request(method=method, url=url, **kwargs)
  File "/Users/temitopebadekale/opt/anaconda3/envs/py3.10/lib/python3.10/site-packages/requests/sessions.py", line 589, in request
    resp = self.send(prep, **send_kwargs)
  File "/Users/temitopebadekale/opt/anaconda3/envs/py3.10/lib/python3.10/site-packages/requests/sessions.py", line 703, in send
    r = adapter.send(request, **kwargs)
  File "/Users/temitopebadekale/opt/anaconda3/envs/py3.10/lib/python3.10/site-packages/requests/adapters.py", line 700, in send
    raise ConnectionError(e, request=request)
requests.exceptions.ConnectionError: HTTPConnectionPool(host='localhost', port=8000): Max retries exceeded with url: /v1/patients?offset=0&limit=100&sort_field=last_name&sort_dir=asc (Caused by NewConnectionError('<urllib3.connection.HTTPConnection object at 0x11bdc3910>: Failed to establish a new connection: [Errno 61] Connection refused'))
